{"uuid": "7db69558-5679-499c-9dd5-5cb889c48f20", "children": ["08305ee7-3ccf-4cbd-b1da-b0c825bf4ef7"], "befores": [{"name": "Prepare for the test", "status": "broken", "statusDetails": {"message": "urllib3.exceptions.MaxRetryError: HTTPConnectionPool(host='192.168.0.121', port=4444): Max retries exceeded with url: /wd/hub/session (Caused by NewConnectionError('<urllib3.connection.HTTPConnection object at 0x0000021165AA1A60>: Failed to establish a new connection: [WinError 10061] Подключение не установлено, т.к. конечный компьютер отверг запрос на подключение'))\n", "trace": "  File \"e:\\project2\\venv\\lib\\site-packages\\pluggy\\_callers.py\", line 167, in _multicall\n    teardown.throw(outcome._exception)\n  File \"e:\\project2\\venv\\lib\\site-packages\\_pytest\\setuponly.py\", line 36, in pytest_fixture_setup\n    return (yield)\n  File \"e:\\project2\\venv\\lib\\site-packages\\pluggy\\_callers.py\", line 103, in _multicall\n    res = hook_impl.function(*args)\n  File \"e:\\project2\\venv\\lib\\site-packages\\_pytest\\fixtures.py\", line 1139, in pytest_fixture_setup\n    result = call_fixture_func(fixturefunc, request, kwargs)\n  File \"e:\\project2\\venv\\lib\\site-packages\\_pytest\\fixtures.py\", line 890, in call_fixture_func\n    fixture_result = next(generator)\n  File \"E:\\pythonProject\\pytestdemo\\conftest.py\", line 41, in browser\n    driver = webdriver.Remote(command_executor=f\"http://{executor}:4444/wd/hub\",\n  File \"e:\\project2\\venv\\lib\\site-packages\\selenium\\webdriver\\remote\\webdriver.py\", line 157, in __init__\n    self.start_session(capabilities, browser_profile)\n  File \"e:\\project2\\venv\\lib\\site-packages\\selenium\\webdriver\\remote\\webdriver.py\", line 252, in start_session\n    response = self.execute(Command.NEW_SESSION, parameters)\n  File \"e:\\project2\\venv\\lib\\site-packages\\selenium\\webdriver\\remote\\webdriver.py\", line 319, in execute\n    response = self.command_executor.execute(driver_command, params)\n  File \"e:\\project2\\venv\\lib\\site-packages\\selenium\\webdriver\\remote\\remote_connection.py\", line 374, in execute\n    return self._request(command_info[0], url, body=data)\n  File \"e:\\project2\\venv\\lib\\site-packages\\selenium\\webdriver\\remote\\remote_connection.py\", line 402, in _request\n    resp = http.request(method, url, body=body, headers=headers)\n  File \"e:\\project2\\venv\\lib\\site-packages\\urllib3\\request.py\", line 78, in request\n    return self.request_encode_body(\n  File \"e:\\project2\\venv\\lib\\site-packages\\urllib3\\request.py\", line 170, in request_encode_body\n    return self.urlopen(method, url, **extra_kw)\n  File \"e:\\project2\\venv\\lib\\site-packages\\urllib3\\poolmanager.py\", line 375, in urlopen\n    response = conn.urlopen(method, u.request_uri, **kw)\n  File \"e:\\project2\\venv\\lib\\site-packages\\urllib3\\connectionpool.py\", line 813, in urlopen\n    return self.urlopen(\n  File \"e:\\project2\\venv\\lib\\site-packages\\urllib3\\connectionpool.py\", line 813, in urlopen\n    return self.urlopen(\n  File \"e:\\project2\\venv\\lib\\site-packages\\urllib3\\connectionpool.py\", line 813, in urlopen\n    return self.urlopen(\n  File \"e:\\project2\\venv\\lib\\site-packages\\urllib3\\connectionpool.py\", line 785, in urlopen\n    retries = retries.increment(\n  File \"e:\\project2\\venv\\lib\\site-packages\\urllib3\\util\\retry.py\", line 592, in increment\n    raise MaxRetryError(_pool, url, error or ResponseError(cause))\n"}, "start": 1726918535087, "stop": 1726918544278}], "start": 1726918535087, "stop": 1726918544402}